Traceback (most recent call last):
  File "fake_sensors.py", line 53, in <module>
    mainloop(world, i, localhost)
  File "fake_sensors.py", line 13, in mainloop
    alert_server(str(plant_num), state, use_localhost)
  File "fake_sensors.py", line 25, in alert_server
    urllib.urlopen('http://169.229.63.33:8888/sensorupdated/' + plant_num + '/' + sensor_data)
  File "/System/Library/Frameworks/Python.framework/Versions/2.6/lib/python2.6/urllib.py", line 87, in urlopen
    return opener.open(url)
  File "/System/Library/Frameworks/Python.framework/Versions/2.6/lib/python2.6/urllib.py", line 203, in open
    return getattr(self, name)(url)
  File "/System/Library/Frameworks/Python.framework/Versions/2.6/lib/python2.6/urllib.py", line 341, in open_http
    errcode, errmsg, headers = h.getreply()
  File "/System/Library/Frameworks/Python.framework/Versions/2.6/lib/python2.6/httplib.py", line 1024, in getreply
    response = self._conn.getresponse()
  File "/System/Library/Frameworks/Python.framework/Versions/2.6/lib/python2.6/httplib.py", line 950, in getresponse
    response.begin()
  File "/System/Library/Frameworks/Python.framework/Versions/2.6/lib/python2.6/httplib.py", line 390, in begin
    version, status, reason = self._read_status()
  File "/System/Library/Frameworks/Python.framework/Versions/2.6/lib/python2.6/httplib.py", line 348, in _read_status
    line = self.fp.readline()
  File "/System/Library/Frameworks/Python.framework/Versions/2.6/lib/python2.6/socket.py", line 395, in readline
    data = recv(1)
IOError: [Errno socket error] [Errno 54] Connection reset by peer
