Traceback (most recent call last):
  File "fake_sensors.py", line 53, in <module>
    mainloop(world, i, localhost)
  File "fake_sensors.py", line 13, in mainloop
    alert_server(str(plant_num), state, use_localhost)
  File "fake_sensors.py", line 25, in alert_server
    urllib.urlopen('http://169.229.63.33:8888/sensorupdated/' + plant_num + '/' + sensor_data)
  File "/Library/Frameworks/Python.framework/Versions/2.7/lib/python2.7/urllib.py", line 86, in urlopen
    return opener.open(url)
  File "/Library/Frameworks/Python.framework/Versions/2.7/lib/python2.7/urllib.py", line 207, in open
    return getattr(self, name)(url)
  File "/Library/Frameworks/Python.framework/Versions/2.7/lib/python2.7/urllib.py", line 351, in open_http
    'got a bad status line', None)
IOError: ('http protocol error', 0, 'got a bad status line', None)
